Workbook
Name IQ_CH: 110000
Name IQ_CQ: 5000
Name IQ_CY: 10000
Name IQ_DAILY: 500000
Name IQ_FH: 100000
Name IQ_FQ: 500
Name IQ_FY: 1000
Name IQ_LTM: 2000
Name IQ_MONTH: 15000
Name IQ_NTM: 6000
Name IQ_WEEK: 50000
Name IQ_YTD: 3000
Name UPDATE: 'Data Sheet'!$E$1

Sheet Financials>

Sheet HistoricalFS
B2: ="Historical Financial Statement -"&'Data Sheet'!B1 -> Historical Financial Statement -ASIAN PAINTS LTD
B3: Years | C3: ='Data Sheet'!B16 -> 42825 | D3: ='Data Sheet'!C16 -> 43190 | E3: ='Data Sheet'!D16 -> 43555 | F3: ='Data Sheet'!E16 -> 43921 | G3: ='Data Sheet'!F16 -> 44286 | H3: ='Data Sheet'!G16 -> 44651 | I3: ='Data Sheet'!H16 -> 45016 | J3: ='Data Sheet'!I16 -> 45382 | ... L3: ='Data Sheet'!K16 -> 46112
A5: # | B5: Income Statement
B6: Sales | C6: =IFERROR('Data Sheet'!B17,0) -> 15061.99 | D6: =IFERROR('Data Sheet'!C17,0) -> 16824.55 | E6: =IFERROR('Data Sheet'!D17,0) -> 19240.13 | F6: =IFERROR('Data Sheet'!E17,0) -> 20211.25 | G6: =IFERROR('Data Sheet'!F17,0) -> 21712.79 | H6: =IFERROR('Data Sheet'!G17,0) -> 29101.28 | I6: =IFERROR('Data Sheet'!H17,0) -> 34488.59 | J6: =IFERROR('Data Sheet'!I17,0) -> 35494.73 | ... L6: =IFERROR('Data Sheet'!K17,0) -> 35583.54
B7: Sales Growth | C7: - | D7: =D6/C6-1 -> 0.11702039 | E7: =E6/D6-1 -> 0.14357472 | F7: =F6/E6-1 -> 0.050473671 | G7: =G6/F6-1 -> 0.074292288 | H7: =H6/G6-1 -> 0.34028285 | I7: =I6/H6-1 -> 0.18512278 | J7: =J6/I6-1 -> 0.029173127 | K7: =K6/J6-1 -> -0.044770308 | L7: =L6/K6-1 -> 0.049487961
B9: COGS | C9: =IFERROR(SUM('Data Sheet'!B18,'Data Sheet'!B20,'Data Sheet'!B21)-1*'Data Sheet'!B19,0) -> 8692.77 | D9: =IFERROR(SUM('Data Sheet'!C18,'Data Sheet'!C20,'Data Sheet'!C21)-1*'Data Sheet'!C19,0) -> 10072.28 | E9: =IFERROR(SUM('Data Sheet'!D18,'Data Sheet'!D20,'Data Sheet'!D21)-1*'Data Sheet'!D19,0) -> 11663.12 | F9: =IFERROR(SUM('Data Sheet'!E18,'Data Sheet'!E20,'Data Sheet'!E21)-1*'Data Sheet'!E19,0) -> 11786.75 | G9: =IFERROR(SUM('Data Sheet'!F18,'Data Sheet'!F20,'Data Sheet'!F21)-1*'Data Sheet'!F19,0) -> 12487.46 | H9: =IFERROR(SUM('Data Sheet'!G18,'Data Sheet'!G20,'Data Sheet'!G21)-1*'Data Sheet'!G19,0) -> 18795.96 | I9: =IFERROR(SUM('Data Sheet'!H18,'Data Sheet'!H20,'Data Sheet'!H21)-1*'Data Sheet'!H19,0) -> 21730.29 | J9: =IFERROR(SUM('Data Sheet'!I18,'Data Sheet'!I20,'Data Sheet'!I21)-1*'Data Sheet'!I19,0) -> 20675.07 | ... L9: =IFERROR(SUM('Data Sheet'!K18,'Data Sheet'!K20,'Data Sheet'!K21)-1*'Data Sheet'!K19,0) -> 20679.9
B10: COGS % Sales | C10: =C9/C6 -> 0.5771329 | D10: =D9/D6 -> 0.59866564 | E10: =E9/E6 -> 0.60618717 | F10: =F9/F6 -> 0.58317769 | G10: =G9/G6 -> 0.57512001 | H10: =H9/H6 -> 0.64588087 | I10: =I9/I6 -> 0.63007186 | J10: =J9/J6 -> 0.58248281 | ... L10: =L9/L6 -> 0.58116477
B12: Gross Profit | C12: =C6-C9 -> 6369.22 | D12: =D6-D9 -> 6752.27 | E12: =E6-E9 -> 7577.01 | F12: =F6-F9 -> 8424.5 | G12: =G6-G9 -> 9225.33 | H12: =H6-H9 -> 10305.32 | I12: =I6-I9 -> 12758.3 | J12: =J6-J9 -> 14819.66 | ... L12: =L6-L9 -> 14903.64
B13: Gross Margins | C13: =C12/C6 -> 0.4228671 | D13: =D12/D6 -> 0.40133436 | E13: =E12/E6 -> 0.39381283 | F13: =F12/F6 -> 0.41682231 | G13: =G12/G6 -> 0.42487999 | H13: =H12/H6 -> 0.35411913 | I13: =I12/I6 -> 0.36992814 | J13: =J12/J6 -> 0.41751719 | ... L13: =L12/L6 -> 0.41883523
B15: Selling and admin expenses | C15: =IFERROR(SUM('Data Sheet'!B23:B24),0) -> 2335.57 | D15: =IFERROR(SUM('Data Sheet'!C23:C24),0) -> 2426.37 | E15: =IFERROR(SUM('Data Sheet'!D23:D24),0) -> 2569.38 | F15: =IFERROR(SUM('Data Sheet'!E23:E24),0) -> 2891.46 | G15: =IFERROR(SUM('Data Sheet'!F23:F24),0) -> 2822.12 | H15: =IFERROR(SUM('Data Sheet'!G23:G24),0) -> 3707.1 | I15: =IFERROR(SUM('Data Sheet'!H23:H24),0) -> 4462.05 | J15: =IFERROR(SUM('Data Sheet'!I23:I24),0) -> 4899.76 | ... L15: =IFERROR(SUM('Data Sheet'!K23:K24),0) -> 5394.18
B16: S&G as % Sales | C16: =C15/C6 -> 0.15506384 | D16: =D15/D6 -> 0.14421604 | E16: =E15/E6 -> 0.13354276 | F16: =F15/F6 -> 0.14306191 | G16: =G15/G6 -> 0.12997501 | H16: =H15/H6 -> 0.12738615 | I16: =I15/I6 -> 0.12937757 | J16: =J15/J6 -> 0.1380419 | ... L16: =L15/L6 -> 0.151592
B18: EBITDA | C18: =C12-C15 -> 4033.65 | D18: =D12-D15 -> 4325.9 | E18: =E12-E15 -> 5007.63 | F18: =F12-F15 -> 5533.04 | G18: =G12-G15 -> 6403.21 | H18: =H12-H15 -> 6598.22 | I18: =I12-I15 -> 8296.25 | J18: =J12-J15 -> 9919.9 | ... L18: =L12-L15 -> 9509.46
B19: EBITDA Margins | C19: =C18/C6 -> 0.26780326 | D19: =D18/D6 -> 0.25711832 | E19: =E18/E6 -> 0.26027007 | F19: =F18/F6 -> 0.27376041 | G19: =G18/G6 -> 0.29490498 | H19: =H18/H6 -> 0.22673298 | I19: =I18/I6 -> 0.24055057 | J19: =J18/J6 -> 0.27947529 | ... L19: =L18/L6 -> 0.26724323
B21: Interest | C21: ='Data Sheet'!B27 -> 37.33 | D21: ='Data Sheet'!C27 -> 41.47 | E21: ='Data Sheet'!D27 -> 110.47 | F21: ='Data Sheet'!E27 -> 102.33 | G21: ='Data Sheet'!F27 -> 91.63 | H21: ='Data Sheet'!G27 -> 95.41 | I21: ='Data Sheet'!H27 -> 144.45 | J21: ='Data Sheet'!I27 -> 205.17 | ... L21: ='Data Sheet'!K27 -> 195.41
B22: Interest % Sales | C22: =C21/C6 -> 0.0024784242 | D22: =D21/D6 -> 0.0024648505 | E22: =E21/E6 -> 0.0057416452 | F22: =F21/F6 -> 0.0050630218 | G22: =G21/G6 -> 0.0042200933 | H22: =H21/H6 -> 0.0032785499 | I22: =I21/I6 -> 0.0041883417 | J22: =J21/J6 -> 0.0057802947 | ... L22: =L21/L6 -> 0.005491584
B24: Depreciation | C24: ='Data Sheet'!B26 -> 334.79 | D24: ='Data Sheet'!C26 -> 360.47 | E24: ='Data Sheet'!D26 -> 622.14 | F24: ='Data Sheet'!E26 -> 780.5 | G24: ='Data Sheet'!F26 -> 791.27 | H24: ='Data Sheet'!G26 -> 816.36 | I24: ='Data Sheet'!H26 -> 858.02 | J24: ='Data Sheet'!I26 -> 853 | ... L24: ='Data Sheet'!K26 -> 1228.85
B25: Depreciation % Sales | C25: =C24/C6 -> 0.022227475 | D25: =D24/D6 -> 0.021425239 | E25: =E24/E6 -> 0.03233554 | F25: =F24/F6 -> 0.038617107 | G25: =G24/G6 -> 0.036442576 | H25: =H24/H6 -> 0.028052374 | I25: =I24/I6 -> 0.024878373 | J25: =J24/J6 -> 0.024031737 | ... L25: =L24/L6 -> 0.034534226
B27: Earnings before tax | C27: =IFERROR(C18-SUM(C21,C24),0) -> 3661.53 | D27: =IFERROR(D18-SUM(D21,D24),0) -> 3923.96 | E27: =IFERROR(E18-SUM(E21,E24),0) -> 4275.02 | F27: =IFERROR(F18-SUM(F21,F24),0) -> 4650.21 | G27: =IFERROR(G18-SUM(G21,G24),0) -> 5520.31 | H27: =IFERROR(H18-SUM(H21,H24),0) -> 5686.45 | I27: =IFERROR(I18-SUM(I21,I24),0) -> 7293.78 | J27: =IFERROR(J18-SUM(J21,J24),0) -> 8861.73 | ... L27: =IFERROR(L18-SUM(L21,L24),0) -> 8085.2
B28: EBT % Sales | C28: =C27/C6 -> 0.24309736 | D28: =D27/D6 -> 0.23322823 | E28: =E27/E6 -> 0.22219289 | F28: =F27/F6 -> 0.23008028 | G28: =G27/G6 -> 0.25424232 | H28: =H27/H6 -> 0.19540206 | I28: =I27/I6 -> 0.21148386 | J28: =J27/J6 -> 0.24966326 | ... L28: =L27/L6 -> 0.22721742
B30: Tax | C30: =IFERROR('Data Sheet'!B29,0) -> 943.29 | D30: =IFERROR('Data Sheet'!C29,0) -> 1040.96 | E30: =IFERROR('Data Sheet'!D29,0) -> 1098.06 | F30: =IFERROR('Data Sheet'!E29,0) -> 854.85 | G30: =IFERROR('Data Sheet'!F29,0) -> 1097.6 | H30: =IFERROR('Data Sheet'!G29,0) -> 1102.91 | I30: =IFERROR('Data Sheet'!H29,0) -> 1493.5 | J30: =IFERROR('Data Sheet'!I29,0) -> 1790.08 | ... L30: =IFERROR('Data Sheet'!K29,0) -> 1608.75
B31: Tax % Sales | C31: =C30/C27 -> 0.25762181 | D31: =D30/D27 -> 0.26528303 | E31: =E30/E27 -> 0.25685494 | F31: =F30/F27 -> 0.18383041 | G31: =G30/G27 -> 0.19882941 | H31: =H30/H27 -> 0.19395405 | I31: =I30/I27 -> 0.20476351 | J31: =J30/J27 -> 0.20200119 | ... L31: =L30/L27 -> 0.19897467
B33: Net Profit | C33: =C27-C30 -> 2718.24 | D33: =D27-D30 -> 2883 | E33: =E27-E30 -> 3176.96 | F33: =F27-F30 -> 3795.36 | G33: =G27-G30 -> 4422.71 | H33: =H27-H30 -> 4583.54 | I33: =I27-I30 -> 5800.28 | J33: =J27-J30 -> 7071.65 | ... L33: =L27-L30 -> 6476.45
B34: Net Margins | C34: =C33/C6 -> 0.18047018 | D34: =D33/D6 -> 0.17135674 | E34: =E33/E6 -> 0.16512155 | F34: =F33/F6 -> 0.18778453 | G34: =G33/G6 -> 0.20369146 | H34: =H33/H6 -> 0.15750304 | I34: =I33/I6 -> 0.16817968 | J34: =J33/J6 -> 0.19923098 | ... L34: =L33/L6 -> 0.18200691
B36: No. of Equity Shares | C36: =IFERROR('Data Sheet'!B93,0) -> 95.92 | D36: =IFERROR('Data Sheet'!C93,0) -> 95.92 | E36: =IFERROR('Data Sheet'!D93,0) -> 95.92 | F36: =IFERROR('Data Sheet'!E93,0) -> 95.92 | G36: =IFERROR('Data Sheet'!F93,0) -> 95.92 | H36: =IFERROR('Data Sheet'!G93,0) -> 95.92 | I36: =IFERROR('Data Sheet'!H93,0) -> 95.92 | J36: =IFERROR('Data Sheet'!I93,0) -> 95.92 | ... L36: =IFERROR('Data Sheet'!K93,0) -> 95.92
B38: Earnings per Share | C38: =IFERROR(C33/C36,0) -> 28.338616 | D38: =IFERROR(D33/D36,0) -> 30.056297 | E38: =IFERROR(E33/E36,0) -> 33.120934 | F38: =IFERROR(F33/F36,0) -> 39.567973 | G38: =IFERROR(G33/G36,0) -> 46.108319 | H38: =IFERROR(H33/H36,0) -> 47.785029 | I38: =IFERROR(I33/I36,0) -> 60.469975 | J38: =IFERROR(J33/J36,0) -> 73.724458 | ... L38: =IFERROR(L33/L36,0) -> 67.519287
B39: EPS Growth % | D39: =IFERROR((D38/C38)-1,0) -> 0.060612749 | E39: =IFERROR((E38/D38)-1,0) -> 0.10196323 | F39: =IFERROR((F38/E38)-1,0) -> 0.19465149 | G39: =IFERROR((G38/F38)-1,0) -> 0.16529394 | H39: =IFERROR((H38/G38)-1,0) -> 0.036364582 | I39: =IFERROR((I38/H38)-1,0) -> 0.26545858 | J39: =IFERROR((J38/I38)-1,0) -> 0.21919114 | K39: =IFERROR((K38/J38)-1,0) -> -0.15645288 | L39: =IFERROR((L38/K38)-1,0) -> 0.085692684
B41: Dividend per Share | C41: =IFERROR('Data Sheet'!B31/HistoricalFS!C38,0) -> 34.863383 | D41: =IFERROR('Data Sheet'!C31/HistoricalFS!D38,0) -> 27.764565 | E41: =IFERROR('Data Sheet'!D31/HistoricalFS!E38,0) -> 30.408563 | F41: =IFERROR('Data Sheet'!E31/HistoricalFS!F38,0) -> 29.090193 | G41: =IFERROR('Data Sheet'!F31/HistoricalFS!G38,0) -> 37.133646 | H41: =IFERROR('Data Sheet'!G31/HistoricalFS!H38,0) -> 38.440282 | I41: =IFERROR('Data Sheet'!H31/HistoricalFS!I38,0) -> 40.687134 | J41: =IFERROR('Data Sheet'!I31/HistoricalFS!J38,0) -> 43.325378 | ... L41: =IFERROR('Data Sheet'!K31/HistoricalFS!L38,0) -> 39.067356
B42: Dividened payout ratio | C42: =IFERROR(C41/C38,0) -> 1.230243 | D42: =IFERROR(D41/D38,0) -> 0.92375201 | E42: =IFERROR(E41/E38,0) -> 0.91810704 | F42: =IFERROR(F41/F38,0) -> 0.73519544 | G42: =IFERROR(G41/G38,0) -> 0.80535674 | H42: =IFERROR(H41/H38,0) -> 0.80444195 | I42: =IFERROR(I41/I38,0) -> 0.67284854 | J42: =IFERROR(J41/J38,0) -> 0.58766628 | ... L42: =IFERROR(L41/L38,0) -> 0.57861031
B44: Retained earnings | C44: =IFERROR(IF(C38>C41,(1-C42),0),0) -> 0 | D44: =IFERROR(1-D42,0) -> 0.07624799 | E44: =IFERROR(1-E42,0) -> 0.081892964 | F44: =IFERROR(1-F42,0) -> 0.26480456 | G44: =IFERROR(1-G42,0) -> 0.19464326 | H44: =IFERROR(1-H42,0) -> 0.19555805 | I44: =IFERROR(1-I42,0) -> 0.32715146 | J44: =IFERROR(1-J42,0) -> 0.41233372 | K44: =IFERROR(1-K42,0) -> 0.38493685 | L44: =IFERROR(1-L42,0) -> 0.42138969
A47: # | B47: Balance Sheet
B48: Equity Share Capital | C48: =IFERROR('Data Sheet'!B57,0) -> 95.92 | D48: =IFERROR('Data Sheet'!C57,0) -> 95.92 | E48: =IFERROR('Data Sheet'!D57,0) -> 95.92 | F48: =IFERROR('Data Sheet'!E57,0) -> 95.92 | G48: =IFERROR('Data Sheet'!F57,0) -> 95.92 | H48: =IFERROR('Data Sheet'!G57,0) -> 95.92 | I48: =IFERROR('Data Sheet'!H57,0) -> 95.92 | J48: =IFERROR('Data Sheet'!I57,0) -> 95.92 | ... L48: =IFERROR('Data Sheet'!K57,0) -> 95.92
B49: Reserves | C49: =IFERROR('Data Sheet'!B58,0) -> 7507.97 | D49: =IFERROR('Data Sheet'!C58,0) -> 8314.31 | E49: =IFERROR('Data Sheet'!D58,0) -> 9374.63 | F49: =IFERROR('Data Sheet'!E58,0) -> 10034.24 | G49: =IFERROR('Data Sheet'!F58,0) -> 12710.37 | H49: =IFERROR('Data Sheet'!G58,0) -> 13715.64 | I49: =IFERROR('Data Sheet'!H58,0) -> 15896.31 | J49: =IFERROR('Data Sheet'!I58,0) -> 18632.38 | ... L49: =IFERROR('Data Sheet'!K58,0) -> 21275.67
B50: Borrowings | C50: =IFERROR('Data Sheet'!B59,0) -> 560.34 | D50: =IFERROR('Data Sheet'!C59,0) -> 533.43 | E50: =IFERROR('Data Sheet'!D59,0) -> 1319.6 | F50: =IFERROR('Data Sheet'!E59,0) -> 1118.5 | G50: =IFERROR('Data Sheet'!F59,0) -> 1093.12 | H50: =IFERROR('Data Sheet'!G59,0) -> 1586.88 | I50: =IFERROR('Data Sheet'!H59,0) -> 1932.62 | J50: =IFERROR('Data Sheet'!I59,0) -> 2474.38 | ... L50: =IFERROR('Data Sheet'!K59,0) -> 3928.93
B51: Other Liabilities | C51: =IFERROR('Data Sheet'!B60,0) -> 4240.96 | D51: =IFERROR('Data Sheet'!C60,0) -> 4819.82 | E51: =IFERROR('Data Sheet'!D60,0) -> 5458.69 | F51: =IFERROR('Data Sheet'!E60,0) -> 4889.31 | G51: =IFERROR('Data Sheet'!F60,0) -> 6455.93 | H51: =IFERROR('Data Sheet'!G60,0) -> 7559.99 | I51: =IFERROR('Data Sheet'!H60,0) -> 7854.48 | J51: =IFERROR('Data Sheet'!I60,0) -> 8698.09 | ... L51: =IFERROR('Data Sheet'!K60,0) -> 9218.23
B52: Total Liabilities | C52: =IFERROR('Data Sheet'!B61,0) -> 12405.19 | D52: =IFERROR('Data Sheet'!C61,0) -> 13763.48 | E52: =IFERROR('Data Sheet'!D61,0) -> 16248.84 | F52: =IFERROR('Data Sheet'!E61,0) -> 16137.97 | G52: =IFERROR('Data Sheet'!F61,0) -> 20355.34 | H52: =IFERROR('Data Sheet'!G61,0) -> 22958.43 | I52: =IFERROR('Data Sheet'!H61,0) -> 25779.33 | J52: =IFERROR('Data Sheet'!I61,0) -> 29900.77 | ... L52: =IFERROR('Data Sheet'!K61,0) -> 34518.75
B54: Fixed Assets Net Block | C54: =IFERROR('Data Sheet'!B62,0) -> 3303.74 | D54: =IFERROR('Data Sheet'!C62,0) -> 3732.24 | E54: =IFERROR('Data Sheet'!D62,0) -> 6496.56 | F54: =IFERROR('Data Sheet'!E62,0) -> 6272.31 | G54: =IFERROR('Data Sheet'!F62,0) -> 5858.52 | H54: =IFERROR('Data Sheet'!G62,0) -> 5519.06 | I54: =IFERROR('Data Sheet'!H62,0) -> 5770.46 | J54: =IFERROR('Data Sheet'!I62,0) -> 7146.62 | ... L54: =IFERROR('Data Sheet'!K62,0) -> 9640.28
B55: Capital Work in Progress | C55: =IFERROR('Data Sheet'!B63,0) -> 257.54 | D55: =IFERROR('Data Sheet'!C63,0) -> 1405.11 | E55: =IFERROR('Data Sheet'!D63,0) -> 209.67 | F55: =IFERROR('Data Sheet'!E63,0) -> 140.24 | G55: =IFERROR('Data Sheet'!F63,0) -> 182.98 | H55: =IFERROR('Data Sheet'!G63,0) -> 426.43 | I55: =IFERROR('Data Sheet'!H63,0) -> 1019.59 | J55: =IFERROR('Data Sheet'!I63,0) -> 2698.37 | ... L55: =IFERROR('Data Sheet'!K63,0) -> 1848.67
B56: Investments | C56: =IFERROR('Data Sheet'!B64,0) -> 2651.99 | D56: =IFERROR('Data Sheet'!C64,0) -> 2140.7 | E56: =IFERROR('Data Sheet'!D64,0) -> 2568.58 | F56: =IFERROR('Data Sheet'!E64,0) -> 2018.85 | G56: =IFERROR('Data Sheet'!F64,0) -> 4736.8 | H56: =IFERROR('Data Sheet'!G64,0) -> 3247.53 | I56: =IFERROR('Data Sheet'!H64,0) -> 4261.71 | J56: =IFERROR('Data Sheet'!I64,0) -> 4587.92 | ... L56: =IFERROR('Data Sheet'!K64,0) -> 7061.74
B57: Other Assets | C57: =IFERROR('Data Sheet'!B65-SUM('Data Sheet'!B67:B69),0) -> 1317.17 | D57: =IFERROR('Data Sheet'!C65-SUM('Data Sheet'!C67:C69),0) -> 1691.84 | E57: =IFERROR('Data Sheet'!D65-SUM('Data Sheet'!D67:D69),0) -> 1471.96 | F57: =IFERROR('Data Sheet'!E65-SUM('Data Sheet'!E67:E69),0) -> 1738.71 | G57: =IFERROR('Data Sheet'!F65-SUM('Data Sheet'!F67:F69),0) -> 2565.52 | H57: =IFERROR('Data Sheet'!G65-SUM('Data Sheet'!G67:G69),0) -> 2876.66 | I57: =IFERROR('Data Sheet'!H65-SUM('Data Sheet'!H67:H69),0) -> 3036.17 | J57: =IFERROR('Data Sheet'!I65-SUM('Data Sheet'!I67:I69),0) -> 3571.39 | ... L57: =IFERROR('Data Sheet'!K65-SUM('Data Sheet'!K67:K69),0) -> 4688.89
B58: Total Non Current Assets | C58: =IFERROR(SUM(C54:C57),0) -> 7530.44 | D58: =IFERROR(SUM(D54:D57),0) -> 8969.89 | E58: =IFERROR(SUM(E54:E57),0) -> 10746.77 | F58: =IFERROR(SUM(F54:F57),0) -> 10170.11 | G58: =IFERROR(SUM(G54:G57),0) -> 13343.82 | H58: =IFERROR(SUM(H54:H57),0) -> 12069.68 | I58: =IFERROR(SUM(I54:I57),0) -> 14087.93 | J58: =IFERROR(SUM(J54:J57),0) -> 18004.3 | ... L58: =IFERROR(SUM(L54:L57),0) -> 23239.58
...

Sheet Analysis-Historical FS
B2: Asian Paints Ltd. — Historical Financial Statement Analysis
B4: Purpose: To analyse historical revenue, profitability, balance-sheet and cash-flow trends and identify the key factors affecting the company's financial performance.
B6: Table 1: Executive summary
B8: Area | C8: FY25 | D8: FY26 | E8: Change | F8: What changed? | G8: Initial assessment
B9: Revenue from Operations | C9: ₹33,905.6 Cr | D9: ₹35,583.5 Cr | E9: 0.049 | F9: Revenue recovered after FY25 decline | G9: Moderate recovery
B10: Material Cost / Net Sales | C10: 0.577 | D10: 0.563 | E10: -1.4 pp | F10: Material-cost intensity reduced | G10: Positive
B11: Gross Margin | C11: 0.423 | D11: 0.437 | E11: +1.4 pp | F11: Gross profitability improved | G11: Positive
B12: EBITDA | C12: ₹6,326.9 Cr | D12: ₹7,113.1 Cr | E12: 0.124 | F12: EBITDA grew faster than revenue | G12: Strong positive
B13: Decorative & Home Décor Revenue | C13: ₹29,545.3 Cr | D13: ₹30,830.4 Cr | E13: 0.043 | F13: Core business recovered | G13: Moderate
B14: International Revenue | C14: ₹3,066.4 Cr | D14: ₹3,353.6 Cr | E14: 0.094 | F14: Faster growth than group | G14: Positive
B15: Industrial Revenue | C15: ₹1,185.7 Cr | D15: ₹1,332.4 Cr | E15: 0.124 | F15: Stronger growth, smaller base | G15: Positive
B18: Table 2: Revenue Analysis
B20: Metric | C20: FY25 | D20: FY26 | E20: Change | F20: Evidence / Reason | G20: Interpretation
B21: Consolidated Revenue | C21: ₹33,905.6 Cr | D21: ₹35,583.5 Cr | E21: 0.049 | F21: Recovery after FY25 decline | G21: Revenue growth recovered
B22: Decorative & Home Décor | C22: ₹29,545.3 Cr | D22: ₹30,830.4 Cr | E22: 0.043 | F22: Largest contributor; 86.8% of revenue | G22: Core business remained the main growth driver
B23: International | C23: ₹3,066.4 Cr | D23: ₹3,353.6 Cr | E23: 0.094 | F23: Growth led by South Asia | G23: Diversification supported growth
B24: Industrial | C24: ₹1,185.7 Cr | D24: ₹1,332.4 Cr | E24: 0.124 | F24: Faster-growing segment | G24: Positive but smaller contribution
B25: White Teak | C25: — | D25: ₹99 Cr | E25: -0.071 | F25: Subdued decorative-lighting demand and residual BIS-related disruption | G25: Weakness in this business
B26: Weatherseal | C26: — | D26: ₹75 Cr | E26: 0.421 | F26: Broad-based growth; stronger acceptance of Struva | G26: Strong growth within home improvement
B29: Revenue conclusion:
B31: Revenue recovered by 4.9% in FY26 after declining by 4.5% in FY25. The core Decorative & Home Décor segment grew at approximately 4.3%, while International and Industrial businesses grew faster.
B32: Therefore, the recovery was broad-based, although the core business remained the primary contributor because of its much larger revenue base.
B34: TABLE 3 — Cost & Profitability Bridge
B36: Metric | C36: FY25 | D36: FY26 | E36: Change | F36: What happened? | G36: Evidence / Reason | H36: Implication
B37: Revenue | C37: ₹33,905.6 Cr | D37: ₹35,583.5 Cr | E37: 0.049 | F37: Moderate growth | G37: Core + International + Industrial growth | H37: Top-line recovery
B38: Material Cost | C38: ₹19,515.8 Cr | D38: ₹20,001.8 Cr | E38: 0.025 | F38: Absolute cost increased | G38: Cost grew slower than revenue | H38: Better cost efficiency
B39: Material Cost / Sales | C39: 0.577 | D39: 0.563 | E39: -1.4 pp | F39: Cost intensity declined | G39: Benign raw-material environment | H39: Positive
B40: Gross Profit | C40: ₹14,281.6 Cr | D40: ₹15,514.6 Cr | E40: 0.086 | F40: Grew faster than revenue | G40: Lower material-cost intensity | H40: Better product-level profitability
B41: Gross Margin | C41: 0.423 | D41: 0.437 | E41: +1.4 pp | F41: Margin expanded | G41: Raw-material + efficiency factors | H41: Positive
B42: EBITDA | C42: ₹6,326.9 Cr | D42: ₹7,113.1 Cr | E42: 0.124 | F42: Grew much faster than revenue | G42: Cost discipline + efficiency | H42: Strong operating improvement
B43: EBITDA Margin | C43: ~18.7% | D43: ~20.0%* | E43: ↑ | F43: Operating profitability improved | G43: Management commentary | H43: Positive
B45: The most significant improvement in FY26 was profitability rather than sales growth. Although absolute material cost increased, it grew more slowly than revenue, reducing material cost as a percentage of sales from 57.7% to 56.3%.
B46: This supported gross-margin expansion and contributed to EBITDA growing substantially faster than revenue.
B48: TABLE 4 — Business Drivers & Risks
B50: Factor | C50: What the Annual Report says | D50: Type | E50: Financial relevance | F50: How I use it
B51: Innovation / Premiumisation | C51: Portfolio shaped through innovation-led premiumisation and differentiated propositions | D51: Strategic driver | E51: Can support product mix and competitiveness | F51: Supporting evidence
B52: New Products | C52: New products introduced across wood finishes, water-based products and value segments | D52: Strategic driver | E52: Portfolio expansion | F52: Supporting evidence
B53: Dealer / Network Initiatives | C53: Dealer engagement, store upgrades, Colour Ideas/Cubes, Beautiful Homes services | D53: Strategic driver | E53: Consumer reach/network effectiveness | F53: Supporting evidence
B54: B2B / Infrastructure | C54: Infrastructure and construction activity provide a structural opportunity | D54: Macro/industry driver | E54: Supports B2B demand potential | F54: Forward-looking support
B55: Raw Materials | C55: Raw-material costs largely stable/benign for most of FY26 | D55: Cost driver | E55: Supports gross margins | F55: Direct explanation of margin improvement
...

Sheet Ratio Analysis
B2: ="Ratio Analysis -"&'Data Sheet'!B1 -> Ratio Analysis -ASIAN PAINTS LTD
B3: Years | C3: ='Data Sheet'!B16 -> 42825 | D3: ='Data Sheet'!C16 -> 43190 | E3: ='Data Sheet'!D16 -> 43555 | F3: ='Data Sheet'!E16 -> 43921 | G3: ='Data Sheet'!F16 -> 44286 | H3: ='Data Sheet'!G16 -> 44651 | I3: ='Data Sheet'!H16 -> 45016 | J3: ='Data Sheet'!I16 -> 45382 | ... L3: ='Data Sheet'!K16 -> 46112 | M3: Trend | N3: Mean | O3: Median
B5: Sales Growth | D5: =IFERROR(HistoricalFS!D7,0) -> 0.11702039 | E5: =IFERROR(HistoricalFS!E7,0) -> 0.14357472 | F5: =IFERROR(HistoricalFS!F7,0) -> 0.050473671 | G5: =IFERROR(HistoricalFS!G7,0) -> 0.074292288 | H5: =IFERROR(HistoricalFS!H7,0) -> 0.34028285 | I5: =IFERROR(HistoricalFS!I7,0) -> 0.18512278 | J5: =IFERROR(HistoricalFS!J7,0) -> 0.029173127 | K5: =IFERROR(HistoricalFS!K7,0) -> -0.044770308 | L5: =IFERROR(HistoricalFS!L7,0) -> 0.049487961 | N5: =IFERROR(AVERAGE(D5:L5),0) -> 0.10496194 | O5: =IFERROR(MEDIAN(C5:L5),0) -> 0.074292288
B6: EBITDA Growth | D6: =IFERROR((HistoricalFS!D18/HistoricalFS!C18)-1,0) -> 0.072452989 | E6: =IFERROR((HistoricalFS!E18/HistoricalFS!D18)-1,0) -> 0.15759264 | F6: =IFERROR((HistoricalFS!F18/HistoricalFS!E18)-1,0) -> 0.10492189 | G6: =IFERROR((HistoricalFS!G18/HistoricalFS!F18)-1,0) -> 0.15726798 | H6: =IFERROR((HistoricalFS!H18/HistoricalFS!G18)-1,0) -> 0.030455037 | I6: =IFERROR((HistoricalFS!I18/HistoricalFS!H18)-1,0) -> 0.25734668 | J6: =IFERROR((HistoricalFS!J18/HistoricalFS!I18)-1,0) -> 0.1957089 | K6: =IFERROR((HistoricalFS!K18/HistoricalFS!J18)-1,0) -> -0.1318471 | L6: =IFERROR((HistoricalFS!L18/HistoricalFS!K18)-1,0) -> 0.10421169 | N6: =IFERROR(AVERAGE(D6:L6),0) -> 0.10534563 | O6: =IFERROR(MEDIAN(C6:L6),0) -> 0.10492189
B7: EBT Growth | D7: =IFERROR((HistoricalFS!D27/HistoricalFS!C27)-1,0) -> 0.071672224 | E7: =IFERROR((HistoricalFS!E27/HistoricalFS!D27)-1,0) -> 0.089465744 | F7: =IFERROR((HistoricalFS!F27/HistoricalFS!E27)-1,0) -> 0.087763332 | G7: =IFERROR((HistoricalFS!G27/HistoricalFS!F27)-1,0) -> 0.18710983 | H7: =IFERROR((HistoricalFS!H27/HistoricalFS!G27)-1,0) -> 0.030096136 | I7: =IFERROR((HistoricalFS!I27/HistoricalFS!H27)-1,0) -> 0.28265966 | J7: =IFERROR((HistoricalFS!J27/HistoricalFS!I27)-1,0) -> 0.21497084 | K7: =IFERROR((HistoricalFS!K27/HistoricalFS!J27)-1,0) -> -0.16961699 | L7: =IFERROR((HistoricalFS!L27/HistoricalFS!K27)-1,0) -> 0.098737129 | N7: =IFERROR(AVERAGE(D7:L7),0) -> 0.099206433 | O7: =IFERROR(MEDIAN(C7:L7),0) -> 0.089465744
B8: Net Profit Growth | D8: =IFERROR((HistoricalFS!D33/HistoricalFS!C33)-1,0) -> 0.060612749 | E8: =IFERROR((HistoricalFS!E33/HistoricalFS!D33)-1,0) -> 0.10196323 | F8: =IFERROR((HistoricalFS!F33/HistoricalFS!E33)-1,0) -> 0.19465149 | G8: =IFERROR((HistoricalFS!G33/HistoricalFS!F33)-1,0) -> 0.16529394 | H8: =IFERROR((HistoricalFS!H33/HistoricalFS!G33)-1,0) -> 0.036364582 | I8: =IFERROR((HistoricalFS!I33/HistoricalFS!H33)-1,0) -> 0.26545858 | J8: =IFERROR((HistoricalFS!J33/HistoricalFS!I33)-1,0) -> 0.21919114 | K8: =IFERROR((HistoricalFS!K33/HistoricalFS!J33)-1,0) -> -0.15645288 | L8: =IFERROR((HistoricalFS!L33/HistoricalFS!K33)-1,0) -> 0.085692684 | N8: =IFERROR(AVERAGE(D8:L8),0) -> 0.10808617 | O8: =IFERROR(MEDIAN(C8:L8),0) -> 0.10196323
B9: Dividend Growth | D9: =IFERROR(HistoricalFS!D41/HistoricalFS!C41-1,0) -> -0.20361817 | E9: =IFERROR(HistoricalFS!E41/HistoricalFS!D41-1,0) -> 0.095229224 | F9: =IFERROR(HistoricalFS!F41/HistoricalFS!E41-1,0) -> -0.043355195 | G9: =IFERROR(HistoricalFS!G41/HistoricalFS!F41-1,0) -> 0.27650047 | H9: =IFERROR(HistoricalFS!H41/HistoricalFS!G41-1,0) -> 0.035187396 | I9: =IFERROR(HistoricalFS!I41/HistoricalFS!H41-1,0) -> 0.058450465 | J9: =IFERROR(HistoricalFS!J41/HistoricalFS!I41-1,0) -> 0.064842205 | K9: =IFERROR(HistoricalFS!K41/HistoricalFS!J41-1,0) -> -0.1171269 | L9: =IFERROR(HistoricalFS!L41/HistoricalFS!K41-1,0) -> 0.021347126 | N9: =IFERROR(AVERAGE(D9:L9),0) -> 0.020828515 | O9: =IFERROR(MEDIAN(C9:L9),0) -> 0.035187396
B11: Gross Margin | C11: =IFERROR(HistoricalFS!C13,0) -> 0.4228671 | D11: =IFERROR(HistoricalFS!D13,0) -> 0.40133436 | E11: =IFERROR(HistoricalFS!E13,0) -> 0.39381283 | F11: =IFERROR(HistoricalFS!F13,0) -> 0.41682231 | G11: =IFERROR(HistoricalFS!G13,0) -> 0.42487999 | H11: =IFERROR(HistoricalFS!H13,0) -> 0.35411913 | I11: =IFERROR(HistoricalFS!I13,0) -> 0.36992814 | J11: =IFERROR(HistoricalFS!J13,0) -> 0.41751719 | ... L11: =IFERROR(HistoricalFS!L13,0) -> 0.41883523 | N11: =IFERROR(AVERAGE(C11:L11),0) -> 0.40262475 | O11: =IFERROR(MEDIAN(C11:L11),0) -> 0.41147676
B12: EBITDA Margin | C12: =IFERROR(HistoricalFS!C19,0) -> 0.26780326 | D12: =IFERROR(HistoricalFS!D19,0) -> 0.25711832 | E12: =IFERROR(HistoricalFS!E19,0) -> 0.26027007 | F12: =IFERROR(HistoricalFS!F19,0) -> 0.27376041 | G12: =IFERROR(HistoricalFS!G19,0) -> 0.29490498 | H12: =IFERROR(HistoricalFS!H19,0) -> 0.22673298 | I12: =IFERROR(HistoricalFS!I19,0) -> 0.24055057 | J12: =IFERROR(HistoricalFS!J19,0) -> 0.27947529 | ... L12: =IFERROR(HistoricalFS!L19,0) -> 0.26724323 | N12: =IFERROR(AVERAGE(C12:L12),0) -> 0.2621858 | O12: =IFERROR(MEDIAN(C12:L12),0) -> 0.26375665
B13: EBIT Margin | C13: =IFERROR((HistoricalFS!C18-HistoricalFS!C24)/HistoricalFS!C6,0) -> 0.24557578 | D13: =IFERROR((HistoricalFS!D18-HistoricalFS!D24)/HistoricalFS!D6,0) -> 0.23569308 | E13: =IFERROR((HistoricalFS!E18-HistoricalFS!E24)/HistoricalFS!E6,0) -> 0.22793453 | F13: =IFERROR((HistoricalFS!F18-HistoricalFS!F24)/HistoricalFS!F6,0) -> 0.2351433 | G13: =IFERROR((HistoricalFS!G18-HistoricalFS!G24)/HistoricalFS!G6,0) -> 0.25846241 | H13: =IFERROR((HistoricalFS!H18-HistoricalFS!H24)/HistoricalFS!H6,0) -> 0.19868061 | I13: =IFERROR((HistoricalFS!I18-HistoricalFS!I24)/HistoricalFS!I6,0) -> 0.2156722 | J13: =IFERROR((HistoricalFS!J18-HistoricalFS!J24)/HistoricalFS!J6,0) -> 0.25544355 | ... L13: =IFERROR((HistoricalFS!L18-HistoricalFS!L24)/HistoricalFS!L6,0) -> 0.232709 | N13: =IFERROR(AVERAGE(C13:L13),0) -> 0.23290429 | O13: =IFERROR(MEDIAN(C13:L13),0) -> 0.23392615
B14: EBT Margin | C14: =IFERROR(HistoricalFS!C28,0) -> 0.24309736 | D14: =IFERROR(HistoricalFS!D28,0) -> 0.23322823 | E14: =IFERROR(HistoricalFS!E28,0) -> 0.22219289 | F14: =IFERROR(HistoricalFS!F28,0) -> 0.23008028 | G14: =IFERROR(HistoricalFS!G28,0) -> 0.25424232 | H14: =IFERROR(HistoricalFS!H28,0) -> 0.19540206 | I14: =IFERROR(HistoricalFS!I28,0) -> 0.21148386 | J14: =IFERROR(HistoricalFS!J28,0) -> 0.24966326 | ... L14: =IFERROR(HistoricalFS!L28,0) -> 0.22721742 | N14: =IFERROR(AVERAGE(C14:L14),0) -> 0.22836404 | O14: =IFERROR(MEDIAN(C14:L14),0) -> 0.22864885
B15: Net Profit Margin | C15: =IFERROR(HistoricalFS!C34,0) -> 0.18047018 | D15: =IFERROR(HistoricalFS!D34,0) -> 0.17135674 | E15: =IFERROR(HistoricalFS!E34,0) -> 0.16512155 | F15: =IFERROR(HistoricalFS!F34,0) -> 0.18778453 | G15: =IFERROR(HistoricalFS!G34,0) -> 0.20369146 | H15: =IFERROR(HistoricalFS!H34,0) -> 0.15750304 | I15: =IFERROR(HistoricalFS!I34,0) -> 0.16817968 | J15: =IFERROR(HistoricalFS!J34,0) -> 0.19923098 | ... L15: =IFERROR(HistoricalFS!L34,0) -> 0.18200691 | N15: =IFERROR(AVERAGE(C15:L15),0) -> 0.17912826 | O15: =IFERROR(MEDIAN(C15:L15),0) -> 0.17820384
B17: SalesExpenses%Sales | C17: =IFERROR(HistoricalFS!C16,0) -> 0.15506384 | D17: =IFERROR(HistoricalFS!D16,0) -> 0.14421604 | E17: =IFERROR(HistoricalFS!E16,0) -> 0.13354276 | F17: =IFERROR(HistoricalFS!F16,0) -> 0.14306191 | G17: =IFERROR(HistoricalFS!G16,0) -> 0.12997501 | H17: =IFERROR(HistoricalFS!H16,0) -> 0.12738615 | I17: =IFERROR(HistoricalFS!I16,0) -> 0.12937757 | J17: =IFERROR(HistoricalFS!J16,0) -> 0.1380419 | ... L17: =IFERROR(HistoricalFS!L16,0) -> 0.151592 | N17: =IFERROR(AVERAGE(C17:L17),0) -> 0.14043895 | O17: =IFERROR(MEDIAN(C17:L17),0) -> 0.1405519
B18: Depreciation%Sales | C18: =IFERROR(HistoricalFS!C25,0) -> 0.022227475 | D18: =IFERROR(HistoricalFS!D25,0) -> 0.021425239 | E18: =IFERROR(HistoricalFS!E25,0) -> 0.03233554 | F18: =IFERROR(HistoricalFS!F25,0) -> 0.038617107 | G18: =IFERROR(HistoricalFS!G25,0) -> 0.036442576 | H18: =IFERROR(HistoricalFS!H25,0) -> 0.028052374 | I18: =IFERROR(HistoricalFS!I25,0) -> 0.024878373 | J18: =IFERROR(HistoricalFS!J25,0) -> 0.024031737 | ... L18: =IFERROR(HistoricalFS!L25,0) -> 0.034534226 | N18: =IFERROR(AVERAGE(C18:L18),0) -> 0.029281514 | O18: =IFERROR(MEDIAN(C18:L18),0) -> 0.029161436
B19: OperatingIncome%Sales | C19: =C13 -> 0.24557578 | D19: =D13 -> 0.23569308 | E19: =E13 -> 0.22793453 | F19: =F13 -> 0.2351433 | G19: =G13 -> 0.25846241 | H19: =H13 -> 0.19868061 | I19: =I13 -> 0.2156722 | J19: =J13 -> 0.25544355 | ... L19: =L13 -> 0.232709 | N19: =IFERROR(AVERAGE(C19:L19),0) -> 0.23290429 | O19: =IFERROR(MEDIAN(C19:L19),0) -> 0.23392615
B21: Return on Capital Employed | C21: =IFERROR((HistoricalFS!C18-HistoricalFS!C24)/SUM(HistoricalFS!C48:C50),0) -> 0.45305681 | D21: =IFERROR((HistoricalFS!D18-HistoricalFS!D24)/SUM(HistoricalFS!D48:D50),0) -> 0.44337889 | E21: =IFERROR((HistoricalFS!E18-HistoricalFS!E24)/SUM(HistoricalFS!E48:E50),0) -> 0.40643457 | F21: =IFERROR((HistoricalFS!F18-HistoricalFS!F24)/SUM(HistoricalFS!F48:F50),0) -> 0.42249832 | G21: =IFERROR((HistoricalFS!G18-HistoricalFS!G24)/SUM(HistoricalFS!G48:G50),0) -> 0.40375383 | H21: =IFERROR((HistoricalFS!H18-HistoricalFS!H24)/SUM(HistoricalFS!H48:H50),0) -> 0.37548349 | I21: =IFERROR((HistoricalFS!I18-HistoricalFS!I24)/SUM(HistoricalFS!I48:I50),0) -> 0.41496749 | J21: =IFERROR((HistoricalFS!J18-HistoricalFS!J24)/SUM(HistoricalFS!J48:J50),0) -> 0.4276299 | ... L21: =IFERROR((HistoricalFS!L18-HistoricalFS!L24)/SUM(HistoricalFS!L48:L50),0) -> 0.32729011 | N21: =IFERROR(AVERAGE(C21:L21),0) -> 0.40242221 | O21: =IFERROR(MEDIAN(C21:L21),0) -> 0.41070103
B22: Retained Earnings % | C22: =IFERROR(HistoricalFS!C44,0) -> 0 | D22: =IFERROR(HistoricalFS!D44,0) -> 0.07624799 | E22: =IFERROR(HistoricalFS!E44,0) -> 0.081892964 | F22: =IFERROR(HistoricalFS!F44,0) -> 0.26480456 | G22: =IFERROR(HistoricalFS!G44,0) -> 0.19464326 | H22: =IFERROR(HistoricalFS!H44,0) -> 0.19555805 | I22: =IFERROR(HistoricalFS!I44,0) -> 0.32715146 | J22: =IFERROR(HistoricalFS!J44,0) -> 0.41233372 | ... L22: =IFERROR(HistoricalFS!L44,0) -> 0.42138969 | N22: =IFERROR(AVERAGE(C22:L22),0) -> 0.23589585 | O22: =IFERROR(MEDIAN(C22:L22),0) -> 0.23018131
B23: Return on Equity% | C23: =IFERROR(HistoricalFS!C33/SUM(HistoricalFS!C48:C49),0) -> 0.35748018 | D23: =IFERROR(HistoricalFS!D33/SUM(HistoricalFS!D48:D49),0) -> 0.34279681 | E23: =IFERROR(HistoricalFS!E33/SUM(HistoricalFS!E48:E49),0) -> 0.33545676 | F23: =IFERROR(HistoricalFS!F33/SUM(HistoricalFS!F48:F49),0) -> 0.37465943 | G23: =IFERROR(HistoricalFS!G33/SUM(HistoricalFS!G48:G49),0) -> 0.34535451 | H23: =IFERROR(HistoricalFS!H33/SUM(HistoricalFS!H48:H49),0) -> 0.33186258 | I23: =IFERROR(HistoricalFS!I33/SUM(HistoricalFS!I48:I49),0) -> 0.36269363 | J23: =IFERROR(HistoricalFS!J33/SUM(HistoricalFS!J48:J49),0) -> 0.37759167 | ... L23: =IFERROR(HistoricalFS!L33/SUM(HistoricalFS!L48:L49),0) -> 0.30304016 | N23: =IFERROR(AVERAGE(C23:L23),0) -> 0.34384269 | O23: =IFERROR(MEDIAN(C23:L23),0) -> 0.34407566
B24: Self sustained growth rate | C24: =IFERROR(C22*C23,0) -> 0 | D24: =IFERROR(D22*D23,0) -> 0.026137568 | E24: =IFERROR(E22*E23,0) -> 0.027471548 | F24: =IFERROR(F22*F23,0) -> 0.099211527 | G24: =IFERROR(G22*G23,0) -> 0.067220928 | H24: =IFERROR(H22*H23,0) -> 0.0648984 | I24: =IFERROR(I22*I23,0) -> 0.11865575 | J24: =IFERROR(J22*J23,0) -> 0.15569378 | ... L24: =IFERROR(L22*L23,0) -> 0.127698 | N24: =IFERROR(AVERAGE(C24:L24),0) -> 0.080535217 | O24: =IFERROR(MEDIAN(C24:L24),0) -> 0.083216227
B25: Interest Coverage Ratio | C25: =IFERROR((HistoricalFS!C18-HistoricalFS!C24)/HistoricalFS!C21,0) -> 99.085454 | D25: =IFERROR((HistoricalFS!D18-HistoricalFS!D24)/HistoricalFS!D21,0) -> 95.621654 | E25: =IFERROR((HistoricalFS!E18-HistoricalFS!E24)/HistoricalFS!E21,0) -> 39.69847 | F25: =IFERROR((HistoricalFS!F18-HistoricalFS!F24)/HistoricalFS!F21,0) -> 46.443272 | G25: =IFERROR((HistoricalFS!G18-HistoricalFS!G24)/HistoricalFS!G21,0) -> 61.245662 | H25: =IFERROR((HistoricalFS!H18-HistoricalFS!H24)/HistoricalFS!H21,0) -> 60.600147 | I25: =IFERROR((HistoricalFS!I18-HistoricalFS!I24)/HistoricalFS!I21,0) -> 51.493458 | J25: =IFERROR((HistoricalFS!J18-HistoricalFS!J24)/HistoricalFS!J21,0) -> 44.192133 | ... L25: =IFERROR((HistoricalFS!L18-HistoricalFS!L24)/HistoricalFS!L21,0) -> 42.375569 | N25: =IFERROR(AVERAGE(C25:L25),0) -> 57.416984 | O25: =IFERROR(MEDIAN(C25:L25),0) -> 48.968365
B27: Debtor Turnover Ratio | C27: =IFERROR(HistoricalFS!C6/HistoricalFS!C60,0) -> 10.411994 | D27: =IFERROR(HistoricalFS!D6/HistoricalFS!D60,0) -> 9.7216332 | E27: =IFERROR(HistoricalFS!E6/HistoricalFS!E60,0) -> 10.087468 | F27: =IFERROR(HistoricalFS!F6/HistoricalFS!F60,0) -> 11.258369 | G27: =IFERROR(HistoricalFS!G6/HistoricalFS!G60,0) -> 8.344109 | H27: =IFERROR(HistoricalFS!H6/HistoricalFS!H60,0) -> 7.5169136 | I27: =IFERROR(HistoricalFS!I6/HistoricalFS!I60,0) -> 7.4377909 | J27: =IFERROR(HistoricalFS!J6/HistoricalFS!J60,0) -> 7.2600464 | ... L27: =IFERROR(HistoricalFS!L6/HistoricalFS!L60,0) -> 7.9751535 | N27: =IFERROR(AVERAGE(C27:L27),0) -> 8.7873554 | O27: =IFERROR(MEDIAN(C27:L27),0) -> 8.1596312
B28: Creditor Turnover Ratio | C28: =IFERROR(HistoricalFS!C6/HistoricalFS!C51,0) -> 3.551552 | D28: =IFERROR(HistoricalFS!D6/HistoricalFS!D51,0) -> 3.4907009 | E28: =IFERROR(HistoricalFS!E6/HistoricalFS!E51,0) -> 3.524679 | F28: =IFERROR(HistoricalFS!F6/HistoricalFS!F51,0) -> 4.1337633 | G28: =IFERROR(HistoricalFS!G6/HistoricalFS!G51,0) -> 3.3632319 | H28: =IFERROR(HistoricalFS!H6/HistoricalFS!H51,0) -> 3.8493808 | I28: =IFERROR(HistoricalFS!I6/HistoricalFS!I51,0) -> 4.390945 | J28: =IFERROR(HistoricalFS!J6/HistoricalFS!J51,0) -> 4.0807499 | ... L28: =IFERROR(HistoricalFS!L6/HistoricalFS!L51,0) -> 3.8601272 | N28: =IFERROR(AVERAGE(C28:L28),0) -> 3.8158002 | O28: =IFERROR(MEDIAN(C28:L28),0) -> 3.854754
B29: Inventory Turnover | C29: =IFERROR(HistoricalFS!C9/HistoricalFS!C61,0) -> 3.3090859 | D29: =IFERROR(HistoricalFS!D9/HistoricalFS!D61,0) -> 3.7889787 | E29: =IFERROR(HistoricalFS!E9/HistoricalFS!E61,0) -> 3.7027423 | F29: =IFERROR(HistoricalFS!F9/HistoricalFS!F61,0) -> 3.4771123 | G29: =IFERROR(HistoricalFS!G9/HistoricalFS!G61,0) -> 3.2873848 | H29: =IFERROR(HistoricalFS!H9/HistoricalFS!H61,0) -> 3.0547735 | I29: =IFERROR(HistoricalFS!I9/HistoricalFS!I61,0) -> 3.498881 | J29: =IFERROR(HistoricalFS!J9/HistoricalFS!J61,0) -> 3.4904 | ... L29: =IFERROR(HistoricalFS!L9/HistoricalFS!L61,0) -> 3.6004555 | N29: =IFERROR(AVERAGE(C29:L29),0) -> 3.4206492 | O29: =IFERROR(MEDIAN(C29:L29),0) -> 3.4837561
B30: Fixed Asset Turnover | C30: =IFERROR(HistoricalFS!C6/HistoricalFS!C54,0) -> 4.5590724 | D30: =IFERROR(HistoricalFS!D6/HistoricalFS!D54,0) -> 4.5078961 | E30: =IFERROR(HistoricalFS!E6/HistoricalFS!E54,0) -> 2.9615874 | F30: =IFERROR(HistoricalFS!F6/HistoricalFS!F54,0) -> 3.2222977 | G30: =IFERROR(HistoricalFS!G6/HistoricalFS!G54,0) -> 3.7061903 | H30: =IFERROR(HistoricalFS!H6/HistoricalFS!H54,0) -> 5.2728689 | I30: =IFERROR(HistoricalFS!I6/HistoricalFS!I54,0) -> 5.9767488 | J30: =IFERROR(HistoricalFS!J6/HistoricalFS!J54,0) -> 4.9666458 | ... L30: =IFERROR(HistoricalFS!L6/HistoricalFS!L54,0) -> 3.6911314 | N30: =IFERROR(AVERAGE(C30:L30),0) -> 4.2541798 | O30: =IFERROR(MEDIAN(C30:L30),0) -> 4.1070432
B31: Capital Turnover Ratio | C31: =IFERROR(HistoricalFS!C6/SUM(HistoricalFS!C49:C50),0) -> 1.8668085 | D31: =IFERROR(HistoricalFS!D6/SUM(HistoricalFS!D49:D50),0) -> 1.9015647 | E31: =IFERROR(HistoricalFS!E6/SUM(HistoricalFS!E49:E50),0) -> 1.7991132 | F31: =IFERROR(HistoricalFS!F6/SUM(HistoricalFS!F49:F50),0) -> 1.8122228 | G31: =IFERROR(HistoricalFS!G6/SUM(HistoricalFS!G49:G50),0) -> 1.5729928 | H31: =IFERROR(HistoricalFS!H6/SUM(HistoricalFS!H49:H50),0) -> 1.9017312 | I31: =IFERROR(HistoricalFS!I6/SUM(HistoricalFS!I49:I50),0) -> 1.9344173 | J31: =IFERROR(HistoricalFS!J6/SUM(HistoricalFS!J49:J50),0) -> 1.6816759 | ... L31: =IFERROR(HistoricalFS!L6/SUM(HistoricalFS!L49:L50),0) -> 1.4117875 | N31: =IFERROR(AVERAGE(C31:L31),0) -> 1.7452442 | O31: =IFERROR(MEDIAN(C31:L31),0) -> 1.805668
B33: Debtor Days | C33: =IFERROR(365/C27,0) -> 35.055726 | D33: =IFERROR(365/D27,0) -> 37.545132 | E33: =IFERROR(365/E27,0) -> 36.183511 | F33: =IFERROR(365/F27,0) -> 32.420325 | G33: =IFERROR(365/G27,0) -> 43.743436 | H33: =IFERROR(365/H27,0) -> 48.557163 | I33: =IFERROR(365/I27,0) -> 49.073711 | J33: =IFERROR(365/J27,0) -> 50.275161 | ... L33: =IFERROR(365/L27,0) -> 45.767144 | N33: =IFERROR(AVERAGE(C33:L33),0) -> 42.505852 | O33: =IFERROR(MEDIAN(C33:L33),0) -> 44.75529
B34: Payable Days | C34: =IFERROR(365/C28,0) -> 102.77197 | D34: =IFERROR(365/D28,0) -> 104.56353 | E34: =IFERROR(365/E28,0) -> 103.55553 | F34: =IFERROR(365/F28,0) -> 88.297268 | G34: =IFERROR(365/G28,0) -> 108.52656 | H34: =IFERROR(365/H28,0) -> 94.820446 | I34: =IFERROR(365/I28,0) -> 83.125613 | J34: =IFERROR(365/J28,0) -> 89.444344 | ... L34: =IFERROR(365/L28,0) -> 94.55647 | N34: =IFERROR(AVERAGE(C34:L34),0) -> 96.294361 | O34: =IFERROR(MEDIAN(C34:L34),0) -> 94.688458
B35: Inventory Days | C35: =IFERROR(365/C29,0) -> 110.30237 | D35: =IFERROR(365/D29,0) -> 96.332027 | E35: =IFERROR(365/E29,0) -> 98.575587 | F35: =IFERROR(365/F29,0) -> 104.97216 | G35: =IFERROR(365/G29,0) -> 111.03051 | H35: =IFERROR(365/H29,0) -> 119.48513 | I35: =IFERROR(365/I29,0) -> 104.31907 | J35: =IFERROR(365/J29,0) -> 104.57254 | ... L35: =IFERROR(365/L29,0) -> 101.37606 | N35: =IFERROR(AVERAGE(C35:L35),0) -> 107.2767 | O35: =IFERROR(MEDIAN(C35:L35),0) -> 104.77235
B36: Cash Conversion cycle(in days) | C36: =SUM(C33,C35)-C34 -> 42.586122 | D36: =SUM(D33,D35)-D34 -> 29.313631 | E36: =SUM(E33,E35)-E34 -> 31.203568 | F36: =SUM(F33,F35)-F34 -> 49.095221 | G36: =SUM(G33,G35)-G34 -> 46.24738 | H36: =SUM(H33,H35)-H34 -> 73.221846 | I36: =SUM(I33,I35)-I34 -> 70.267166 | J36: =SUM(J33,J35)-J34 -> 65.403359 | ... L36: =SUM(L33,L35)-L34 -> 52.586737 | N36: =IFERROR(AVERAGE(C36:L36),0) -> 53.48819 | O36: =IFERROR(MEDIAN(C36:L36),0) -> 50.840979
B38: CFO/Sales | C38: =IFERROR(HistoricalFS!C69/HistoricalFS!C6,0) -> 0.10140294 | D38: =IFERROR(HistoricalFS!D69/HistoricalFS!D6,0) -> 0.12561644 | E38: =IFERROR(HistoricalFS!E69/HistoricalFS!E6,0) -> 0.1283536 | F38: =IFERROR(HistoricalFS!F69/HistoricalFS!F6,0) -> 0.15031975 | G38: =IFERROR(HistoricalFS!G69/HistoricalFS!G6,0) -> 0.16963965 | H38: =IFERROR(HistoricalFS!H69/HistoricalFS!H6,0) -> 0.033898509 | I38: =IFERROR(HistoricalFS!I69/HistoricalFS!I6,0) -> 0.12158891 | J38: =IFERROR(HistoricalFS!J69/HistoricalFS!J6,0) -> 0.17195792 | ... L38: =IFERROR(HistoricalFS!L69/HistoricalFS!L6,0) -> 0.19919828 | N38: =IFERROR(AVERAGE(C38:L38),0) -> 0.13324547 | O38: =IFERROR(MEDIAN(C38:L38),0) -> 0.12941613
B39: CFO/Total Assets | C39: =IFERROR(HistoricalFS!C69/HistoricalFS!C65,0) -> 0.12312024 | D39: =IFERROR(HistoricalFS!D69/HistoricalFS!D65,0) -> 0.15355419 | E39: =IFERROR(HistoricalFS!E69/HistoricalFS!E65,0) -> 0.15198254 | F39: =IFERROR(HistoricalFS!F69/HistoricalFS!F65,0) -> 0.18826098 | G39: =IFERROR(HistoricalFS!G69/HistoricalFS!G65,0) -> 0.18095252 | H39: =IFERROR(HistoricalFS!H69/HistoricalFS!H65,0) -> 0.042968531 | I39: =IFERROR(HistoricalFS!I69/HistoricalFS!I65,0) -> 0.16266637 | J39: =IFERROR(HistoricalFS!J69/HistoricalFS!J65,0) -> 0.20412852 | ... L39: =IFERROR(HistoricalFS!L69/HistoricalFS!L65,0) -> 0.20534289 | N39: =IFERROR(AVERAGE(C39:L39),0) -> 0.15587163 | O39: =IFERROR(MEDIAN(C39:L39),0) -> 0.15811028
B40: CFO/Total Debt | C40: =IFERROR(HistoricalFS!C69/HistoricalFS!C50,0) -> 2.7257201 | D40: =IFERROR(HistoricalFS!D69/HistoricalFS!D50,0) -> 3.9619819 | E40: =IFERROR(HistoricalFS!E69/HistoricalFS!E50,0) -> 1.8714307 | F40: =IFERROR(HistoricalFS!F69/HistoricalFS!F50,0) -> 2.7162718 | G40: =IFERROR(HistoricalFS!G69/HistoricalFS!G50,0) -> 3.3695752 | H40: =IFERROR(HistoricalFS!H69/HistoricalFS!H50,0) -> 0.62165381 | I40: =IFERROR(HistoricalFS!I69/HistoricalFS!I50,0) -> 2.1698161 | J40: =IFERROR(HistoricalFS!J69/HistoricalFS!J50,0) -> 2.4667189 | ... L40: =IFERROR(HistoricalFS!L69/HistoricalFS!L50,0) -> 1.8040993 | N40: =IFERROR(AVERAGE(C40:L40),0) -> 2.3638884 | O40: =IFERROR(MEDIAN(C40:L40),0) -> 2.3182675

Sheet Analysis of ratios
B2: Ratio | C2: Formula | D2: Significance | E2: Number | F2: Reason
B3: Sales Growth | C3: (Current Sales − Previous Sales) / Previous Sales × 100 | D3: Measures the rate of change in revenue; indicates top-line expansion or contraction | E3: FY22 34.03% → FY23 18.51% → FY24 2.92% → FY25 -4.48% → FY26 4.95% | F3: Sales growth recovered in FY26, supported by a recovery in underlying coatings volumes, with India Decorative volume growth of 8.7%, double-digit growth in Industrial and Automotive Protective Coatings, and 9.4% growth in the International business. However, home décor faced near-term retail headwinds and competitive intensity remained a constraint.
B4: EBITDA Growth | C4: (Current EBITDA − Previous EBITDA) / Previous EBITDA × 100 | D4: Measures growth in operating earnings before D&A, interest and tax. | E4: FY22 3.05%, FY23 25.73%, FY24 19.57%, FY25 -13.18%, FY26 10.42% | F4: EBITDA growth was supported by improved operating profitability as material costs moderated, gross margins improved and the Company continued cost optimisation and operating-efficiency initiatives.
B5: EBT Growth | C5: (Current EBT − Previous EBT) / Previous EBT × 100 | D5: Measures growth in profit before tax after operating, depreciation and financing-related effects. | E5: FY22 3.01%, FY23 28.27%, FY24 21.50%, FY25 -16.96%, FY26 9.87% | F5: EBT growth was supported by lower finance costs, primarily due to reduced interest on bank borrowings, bill discounting and other interest expenses. However, the benefit was partly offset by higher depreciation expense.
B6: Net Profit Growth | C6: (Current PAT − Previous PAT) / Previous PAT × 100 | D6: Measures growth in the company's final profit after expenses and tax. | E6: FY22 3.64%, FY23 26.55%, FY24 21.92%, FY25 -15.65%, FY26 8.57% | F6: Improved profitability and stronger margin performance supported growth in net profit.
B7: Dividend Growth | C7: (Current Dividend − Previous Dividend) / Previous Dividend × 100 | D7: Shows how quickly shareholder distributions are changing. | E7: FY22 3.52%, FY23 5.85%, FY24 6.48%, FY25 -11.71%, FY26 2.13% | F7: Dividend increased in line with the company's progressive dividend policy. The payout ratio was maintained at 60%, consistent with the previous three years, reflecting the company's policy of sharing the benefits of growth with shareholders
B9: Gross Margin | C9: Gross Profit / Revenue × 100 | D9: Measures the proportion of revenue left after COGS. Helps assess product-level profitability, pricing and input-cost efficiency. | E9: FY22 35.41% → FY23 36.99% → FY24 41.75% → FY25 40.61% → FY26 41.88% | F9: Improvement was supported by raw-material efficiencies and favourable input-cost conditions, along with a better product mix/premiumisation
B10: EBITDA Margin | C10: EBITDA / Revenue × 100 | D10: Measures operating profitability before D&A, interest and tax. Useful for comparing operating performance relative to revenue. | E10: FY22 22.67% → FY23 24.06% → FY24 27.95% → FY25 25.40% → FY26 26.72% | F10: EBITDA margin improved as the benefit from better gross margins flowed through to operating profitability, supported by operating efficiencies and cost-management initiatives.
B11: EBIT Margin | C11: EBIT / Revenue × 100 | D11: Measures operating profitability after depreciation and amortisation. Shows the effect of using the company's asset base on operating earnings. | E11: FY22 19.87% → FY23 21.57% → FY24 25.54% → FY25 22.37% → FY26 23.27% | F11: Improved operating profitability more than offset the higher depreciation burden from continued investment in capacity and assets.
B12: EBT Margin | C12: EBT / Revenue × 100 | D12: Measures the percentage of revenue remaining as profit before tax, after operating and financing-related effects. | E12: FY22 19.54% → FY23 21.15% → FY24 24.97% → FY25 21.70% → FY26 22.72% | F12: Higher operating profitability, together with lower finance costs, reduced the financing burden and improved pre-tax profitability.
B13: Net Profit Margin | C13: PAT / Revenue × 100 | D13: Measures the percentage of revenue ultimately retained as net profit after expenses and tax. Indicates bottom-line profitability. | E13: FY22 15.75% → FY23 16.82% → FY24 19.92% → FY25 17.59% → FY26 18.20% | F13: Improved overall profitability led to better net profit conversion.
B15: SalesExpenses%Sales | C15: Selling & Administrative Expenses / Sales × 100 | D15: Shows how much of revenue is consumed by selling and administrative expenses. Helps assess the company's operating cost intensity. | E15: FY22 12.74% → FY23 12.94% → FY24 13.80% → FY25 15.21% → FY26 15.16% | F15: The slight decline suggests that operating expense growth was broadly controlled despite the company's continued investments in brand building, distribution and services.
... B38: CFO/Total Debt | C38: Cash Flow from Operations / Total Debt × 100 | D38: Indicates the company's ability to generate operating cash relative to its debt obligations. A higher ratio generally indicates stronger cash-flow-based debt servicing capacity. | E38: FY22 62.17% → FY23 216.98% → FY24 246.67% → FY25 193.16% → FY26 180.41% | F38: Operating cash flow remained very strong relative to debt, although cash coverage per rupee of debt declined somewhat during the year.

Sheet Forecasting
B2: ='Data Sheet'!B1&" -"&'Data Sheet'!A17&" forecasting" -> ASIAN PAINTS LTD -Sales forecasting | G2: ='Data Sheet'!B1&" -"&HistoricalFS!B18&" forecasting" -> ASIAN PAINTS LTD -EBITDA forecasting | L2: ='Data Sheet'!B1&" -"&HistoricalFS!B38&" forecasting" -> ASIAN PAINTS LTD -Earnings per Share forecasting
B3: Year Weight | C3: Year | D3: Sales | E3: Sales Growth | G3: Year Weight | H3: Year | I3: EBITDA | J3: EBITDA Growth | L3: Year Weight | M3: Year | N3: EPS | O3: EPS Growth
B4: 1 | C4: ='Data Sheet'!$B$16 -> 42825 | D4: {=TRANSPOSE('Data Sheet'!B17:K17)} -> 15061.99 | G4: 1 | H4: =C4 -> 42825 | I4: {=TRANSPOSE(HistoricalFS!C18:L18)} -> 4033.65 | L4: 1 | M4: =H4 -> 42825 | N4: {=TRANSPOSE(HistoricalFS!C38:L38)} -> 28.338616
B5: =B4+1 -> 2 | C5: =C4+365 -> 43190 | D5: 16824.55 | E5: =D5/D4-1 -> 0.11702039 | G5: =G4+1 -> 2 | H5: =H4+365 -> 43190 | I5: 4325.9 | J5: =I5/I4-1 -> 0.072452989 | L5: =L4+1 -> 2 | M5: =M4+365 -> 43190 | N5: 30.056297 | O5: =N5/N4-1 -> 0.060612749
B6: =B5+1 -> 3 | C6: =C5+365 -> 43555 | D6: 19240.13 | E6: =D6/D5-1 -> 0.14357472 | G6: =G5+1 -> 3 | H6: =H5+365 -> 43555 | I6: 5007.63 | J6: =I6/I5-1 -> 0.15759264 | L6: =L5+1 -> 3 | M6: =M5+365 -> 43555 | N6: 33.120934 | O6: =N6/N5-1 -> 0.10196323
B7: =B6+1 -> 4 | C7: =C6+365 -> 43920 | D7: 20211.25 | E7: =D7/D6-1 -> 0.050473671 | G7: =G6+1 -> 4 | H7: =H6+365 -> 43920 | I7: 5533.04 | J7: =I7/I6-1 -> 0.10492189 | L7: =L6+1 -> 4 | M7: =M6+365 -> 43920 | N7: 39.567973 | O7: =N7/N6-1 -> 0.19465149
B8: =B7+1 -> 5 | C8: =C7+365 -> 44285 | D8: 21712.79 | E8: =D8/D7-1 -> 0.074292288 | G8: =G7+1 -> 5 | H8: =H7+365 -> 44285 | I8: 6403.21 | J8: =I8/I7-1 -> 0.15726798 | L8: =L7+1 -> 5 | M8: =M7+365 -> 44285 | N8: 46.108319 | O8: =N8/N7-1 -> 0.16529394
B9: =B8+1 -> 6 | C9: =C8+365 -> 44650 | D9: 29101.28 | E9: =D9/D8-1 -> 0.34028285 | G9: =G8+1 -> 6 | H9: =H8+365 -> 44650 | I9: 6598.22 | J9: =I9/I8-1 -> 0.030455037 | L9: =L8+1 -> 6 | M9: =M8+365 -> 44650 | N9: 47.785029 | O9: =N9/N8-1 -> 0.036364582
B10: =B9+1 -> 7 | C10: =C9+365 -> 45015 | D10: 34488.59 | E10: =D10/D9-1 -> 0.18512278 | G10: =G9+1 -> 7 | H10: =H9+365 -> 45015 | I10: 8296.25 | J10: =I10/I9-1 -> 0.25734668 | L10: =L9+1 -> 7 | M10: =M9+365 -> 45015 | N10: 60.469975 | O10: =N10/N9-1 -> 0.26545858
B11: =B10+1 -> 8 | C11: =C10+365 -> 45380 | D11: 35494.73 | E11: =D11/D10-1 -> 0.029173127 | G11: =G10+1 -> 8 | H11: =H10+365 -> 45380 | I11: 9919.9 | J11: =I11/I10-1 -> 0.1957089 | L11: =L10+1 -> 8 | M11: =M10+365 -> 45380 | N11: 73.724458 | O11: =N11/N10-1 -> 0.21919114
B12: =B11+1 -> 9 | C12: =C11+365 -> 45745 | D12: 33905.62 | E12: =D12/D11-1 -> -0.044770308 | G12: =G11+1 -> 9 | H12: =H11+365 -> 45745 | I12: 8611.99 | J12: =I12/I11-1 -> -0.1318471 | L12: =L11+1 -> 9 | M12: =M11+365 -> 45745 | N12: 62.190054 | O12: =N12/N11-1 -> -0.15645288
B13: =B12+1 -> 10 | C13: =C12+365 -> 46110 | D13: 35583.54 | E13: =D13/D12-1 -> 0.049487961 | G13: =G12+1 -> 10 | H13: =H12+365 -> 46110 | I13: 9509.46 | J13: =I13/I12-1 -> 0.10421169 | L13: =L12+1 -> 10 | M13: =M12+365 -> 46110 | N13: 67.519287 | O13: =N13/N12-1 -> 0.085692684
B14: =B13+1 -> 11 | C14: =C13+365 -> 46475 | D14: =FORECAST(B14,$D$4:$D$13,$B$4:$B$13) -> 40687.612 | E14: =D14/D13-1 -> 0.14343913 | G14: =G13+1 -> 11 | H14: =H13+365 -> 46475 | I14: =FORECAST(G14,$I$4:$I$13,$G$4:$G$13) -> 10568.289 | J14: =I14/I13-1 -> 0.11134477 | L14: =L13+1 -> 11 | M14: =M13+365 -> 46475 | N14: =FORECAST(L14,$N$4:$N$13,$L$4:$L$13) -> 77.053517 | O14: =N14/N13-1 -> 0.1412075
B15: =B14+1 -> 12 | C15: =C14+365 -> 46840 | D15: =FORECAST(B15,$D$4:$D$13,$B$4:$B$13) -> 43328.551 | E15: =D15/D14-1 -> 0.064907695 | G15: =G14+1 -> 12 | H15: =H14+365 -> 46840 | I15: =FORECAST(G15,$I$4:$I$13,$G$4:$G$13) -> 11249.082 | J15: =I15/I14-1 -> 0.064418509 | L15: =L14+1 -> 12 | M15: =M14+365 -> 46840 | N15: =FORECAST(L15,$N$4:$N$13,$L$4:$L$13) -> 82.174503 | O15: =N15/N14-1 -> 0.066460119
B16: =B15+1 -> 13 | C16: =C15+365 -> 47205 | D16: =FORECAST(B16,$D$4:$D$13,$B$4:$B$13) -> 45969.49 | E16: =D16/D15-1 -> 0.060951475 | G16: =G15+1 -> 13 | H16: =H15+365 -> 47205 | I16: =FORECAST(G16,$I$4:$I$13,$G$4:$G$13) -> 11929.875 | J16: =I16/I15-1 -> 0.060519906 | L16: =L15+1 -> 13 | M16: =M15+365 -> 47205 | N16: =FORECAST(L16,$N$4:$N$13,$L$4:$L$13) -> 87.295489 | O16: =N16/N15-1 -> 0.062318429
B17: =B16+1 -> 14 | C17: =C16+365 -> 47570 | D17: =FORECAST(B17,$D$4:$D$13,$B$4:$B$13) -> 48610.429 | E17: =D17/D16-1 -> 0.057449823 | G17: =G16+1 -> 14 | H17: =H16+365 -> 47570 | I17: =FORECAST(G17,$I$4:$I$13,$G$4:$G$13) -> 12610.669 | J17: =I17/I16-1 -> 0.057066262 | L17: =L16+1 -> 14 | M17: =M16+365 -> 47570 | N17: =FORECAST(L17,$N$4:$N$13,$L$4:$L$13) -> 92.416475 | O17: =N17/N16-1 -> 0.058662664
B18: =B17+1 -> 15 | C18: =C17+365 -> 47935 | D18: =FORECAST(B18,$D$4:$D$13,$B$4:$B$13) -> 51251.368 | E18: =D18/D17-1 -> 0.054328652 | G18: =G17+1 -> 15 | H18: =H17+365 -> 47935 | I18: =FORECAST(G18,$I$4:$I$13,$G$4:$G$13) -> 13291.462 | J18: =I18/I17-1 -> 0.05398551 | L18: =L17+1 -> 15 | M18: =M17+365 -> 47935 | N18: =FORECAST(L18,$N$4:$N$13,$L$4:$L$13) -> 97.537461 | O18: =N18/N17-1 -> 0.055412046
B19: =B18+1 -> 16 | C19: =C18+365 -> 48300 | D19: =FORECAST(B19,$D$4:$D$13,$B$4:$B$13) -> 53892.307 | E19: =D19/D18-1 -> 0.051529143 | G19: =G18+1 -> 16 | H19: =H18+365 -> 48300 | I19: =FORECAST(G19,$I$4:$I$13,$G$4:$G$13) -> 13972.256 | J19: =I19/I18-1 -> 0.051220353 | L19: =L18+1 -> 16 | M19: =M18+365 -> 48300 | N19: =FORECAST(L19,$N$4:$N$13,$L$4:$L$13) -> 102.65845 | O19: =N19/N18-1 -> 0.05250276
B22: Forecast Methodology
B23: Item | C23: Details
B24: Method | C24: Simple Linear Regression
B25: Independent Variable(X) | C25: Year Weight(1,2,3….)
B26: Dependent Variable(Y) | C26: Sales/EBITDA/EPS
B27: Historical Period | C27: FY17-FY26
B28: Forecast Period | C28: FY27-FY32
B29: Purpose | C29: Establish a historical trend- based baseline
B31: The regression extrapolates the historical relationship between time and the financial variable; the forecast is therefore a statistical baseline, not a business-driven assumption.
B34: InSample forecasting- Sales | G34: Back-testing- EBITDA | L34: Back-testing- EPS
B35: Year | C35: Regression Forecast | D35: Forecast Error(Actual-Forecast) | E35: Absolute % Error | G35: Year | H35: Regression Forecast | I35: Forecast Error(Actual-Forecast) | J35: Absolute % Error | L35: Year | M35: Regression Forecast | N35: Forecast Error(Actual-Forecast) | O35: Absolute % Error
B36: 2022 | C36: =FORECAST(B9,D4:D8,B4:B8) -> 23616.632 | D36: =D9-C36 -> 5484.648 | E36: =ABS(D36/D9) -> 0.18846759 | G36: 2022 | H36: =FORECAST(G9,I4:I8,G4:G8) -> 6844.564 | I36: =I9-H36 -> -246.344 | J36: =ABS(I36/I9) -> 0.037334918 | L36: 2022 | M36: =FORECAST(L9,N4:N8,L4:L8) -> 48.953753 | N36: =N9-M36 -> -1.1687239 | O36: =ABS(N36/N9) -> 0.024457952
B37: =B36+1 -> 2023 | C37: =FORECAST(B10,D5:D9,B5:B9) -> 29525.836 | D37: =D10-C37 -> 4962.754 | E37: =ABS(D37/D10) -> 0.14389553 | G37: =G36+1 -> 2023 | H37: =FORECAST(G10,I5:I9,G5:G9) -> 7355.666 | I37: =I10-H37 -> 940.584 | J37: =ABS(I37/I10) -> 0.1133746 | L37: =L36+1 -> 2023 | M37: =FORECAST(L10,N5:N9,L5:L9) -> 53.861166 | N37: =N10-M37 -> 6.6088094 | O37: =ABS(N37/N10) -> 0.10929076
B38: =B37+1 -> 2024 | C38: =FORECAST(B11,D6:D10,B6:B10) -> 36766.893 | D38: =D11-C38 -> -1272.163 | E38: =ABS(D38/D11) -> 0.035840898 | G38: =G37+1 -> 2024 | H38: =FORECAST(G11,I6:I10,G6:G10) -> 8660.396 | I38: =I11-H38 -> 1259.504 | J38: =ABS(I38/I11) -> 0.12696741 | L38: =L37+1 -> 2024 | M38: =FORECAST(L11,N6:N10,L6:L10) -> 64.284987 | N38: =N11-M38 -> 9.4394704 | O38: =ABS(N38/N11) -> 0.12803716
B39: =B38+1 -> 2025 | C39: =FORECAST(B12,D7:D11,B7:B11) -> 41204.556 | D39: =D12-C39 -> -7298.936 | E39: =ABS(D39/D12) -> 0.21527216 | G39: =G38+1 -> 2025 | H39: =FORECAST(G12,I7:I11,G7:G11) -> 10550.152 | I39: =I12-H39 -> -1938.162 | J39: =ABS(I39/I12) -> 0.22505391 | L39: =L38+1 -> 2025 | M39: =FORECAST(L12,N7:N11,L7:L11) -> 78.333538 | N39: =N12-M39 -> -16.143484 | O39: =ABS(N39/N12) -> 0.25958305
B40: =B39+1 -> 2026 | C40: =FORECAST(B13,D8:D12,B8:B12) -> 40174.335 | D40: =D13-C40 -> -4590.795 | E40: =ABS(D40/D13) -> 0.12901457 | G40: =G39+1 -> 2026 | H40: =FORECAST(G13,I8:I12,G8:G12) -> 10287.686 | I40: =I13-H40 -> -778.226 | J40: =ABS(I40/I13) -> 0.081837034 | L40: =L39+1 -> 2026 | M40: =FORECAST(L13,N8:N12,L8:L12) -> 75.486437 | N40: =N13-M40 -> -7.9671497 | O40: =ABS(N40/N13) -> 0.11799813
D41: MAPE | E41: =AVERAGE(E36:E40) -> 0.14249815 | I41: MAPE | J41: =AVERAGE(J36:J40) -> 0.11691357 | N41: MAPE | O41: =AVERAGE(O36:O40) -> 0.12787341
B43: Back-testing over FY22–FY26 shows average absolute forecasting errors of 14.25% for Sales, 11.69% for EBITDA and 12.79% for EPS. The errors indicate that a simple time trend can miss significant changes in business performance.
B46: Model Output and Interpretation
B47: The regression forecasts should be treated as statistical baselines rather than standalone investment forecasts. They should be compared with management guidance, industry outlook and company-specific business drivers before being relied upon.
B48: FY27 Sales forecast of ₹40,687.6 crore implies 14.34% growth based on the historical trend. This is a model-derived outcome, not a business assumption.
B49: FY27 EBITDA forecast of ₹10,568.3 crore implies 11.13% growth based on the historical trend. Given the EBITDA model's 11.69% historical MAPE, this estimate should be validated against expected margins, input costs and operating conditions.
...

Sheet Beta-Regression
B2: Regression Beta- 2 years weekly
B4: Asian Paints Weekly Returns | F4: Nifty Returns | I4: Beta Drifting | L4: Asian Paints | V4: Berger Paints | Z4: Kansai Nerolac | AC4: JSW Dulux | AF4: Indigo Paints
B6: Date | C6: Adj. Closing Price | D6: Return | F6: Adj. Closing Price | G6: Return | I6: Levered Raw Beta | J6: =M7 -> 0.96207015 | V6: Adj. Closing Price | W6: Return | Z6: Adj. Closing Price | AA6: Return | AC6: Adj. Closing Price | AD6: Return | AF6: Adj. Closing Price | AG6: Return
B7: 45509 | C7: 2977.1318 | F7: 24367.5 | I7: Raw Beta Weight | J7: 0.67 | L7: Beta | M7: =M26 -> 0.96207015 | V7: 524.14838 | Z7: 285.70441 | AC7: 3068.8447 | AF7: 1418.0793
B8: 45516 | C8: 2984.5239 | D8: =C8/C7-1 -> 0.0024829568 | F8: 24541.15 | G8: =F8/F7-1 -> 0.0071263113 | V8: 542.14081 | W8: =V8/V7-1 -> 0.034326982 | Z8: 282.20242 | AA8: =Z8/Z7-1 -> -0.012257367 | AC8: 2926.2136 | AD8: =AC8/AC7-1 -> -0.046477133 | AF8: 1430.9397 | AG8: =AF8/AF7-1 -> 0.0090688519
B9: 45523 | C9: 3088.8008 | D9: =C9/C8-1 -> 0.034939192 | F9: 24823.15 | G9: =F9/F8-1 -> 0.011490904 | I9: Market Beta | J9: 1 | L9: SUMMARY OUTPUT | V9: 557.71796 | W9: =V9/V8-1 -> 0.028732662 | Z9: 286.28806 | AA9: =Z9/Z8-1 -> 0.014477666 | AC9: 3001.8191 | AD9: =AC9/AC8-1 -> 0.025837303 | AF9: 1444.9465 | AG9: =AF9/AF8-1 -> 0.0097885578
B10: 45530 | C10: 3061.5327 | D10: =C10/C9-1 -> -0.0088280431 | F10: 25235.9 | G10: =F10/F9-1 -> 0.016627624 | I10: Market Beta Weight | J10: 0.33 | V10: 562.99243 | W10: =V10/V9-1 -> 0.0094572445 | Z10: 288.42816 | AA10: =Z10/Z9-1 -> 0.0074753597 | AC10: 3179.4082 | AD10: =AC10/AC9-1 -> 0.059160498 | AF10: 1446.0432 | AG10: =AF10/AF9-1 -> 0.00075897596
B11: 45537 | C11: 3205.366 | D11: =C11/C10-1 -> 0.046980799 | F11: 24852.15 | G11: =F11/F10-1 -> -0.015206511 | L11: Regression Statistics | V11: 587.88611 | W11: =V11/V10-1 -> 0.044216717 | Z11: 297.71817 | AA11: =Z11/Z10-1 -> 0.03220909 | AC11: 3459.4412 | AD11: =AC11/AC10-1 -> 0.08807707 | AF11: 1474.8044 | AG11: =AF11/AF10-1 -> 0.019889606
B12: 45544 | C12: 3287.9553 | D12: =C12/C11-1 -> 0.025765968 | F12: 25356.5 | G12: =F12/F11-1 -> 0.020294003 | I12: Adjusted Beta | J12: =(J6*J7)+(J9*J10) -> 0.974587 | L12: Multiple R | M12: 0.52323038 | V12: 613.86438 | W12: =V12/V11-1 -> 0.044189293 | Z12: 302.92252 | AA12: =Z12/Z11-1 -> 0.01748078 | AC12: 3386.2217 | AD12: =AC12/AC11-1 -> -0.021165119 | AF12: 1497.5345 | AG12: =AF12/AF11-1 -> 0.015412282
B13: 45551 | C13: 3237.9219 | D13: =C13/C12-1 -> -0.015217192 | F13: 25790.949 | G13: =F13/F12-1 -> 0.017133643 | L13: R Square | M13: 0.27377003 | V13: 614.06146 | W13: =V13/V12-1 -> 0.00032105222 | Z13: 293.92435 | AA13: =Z13/Z12-1 -> -0.029704523 | AC13: 3401.3608 | AD13: =AC13/AC12-1 -> 0.0044708119 | AF13: 1476.7485 | AG13: =AF13/AF12-1 -> -0.013880154
B14: 45558 | C14: 3241.6428 | D14: =C14/C13-1 -> 0.0011491776 | F14: 26178.949 | G14: =F14/F13-1 -> 0.015044037 | L14: Adjusted R Square | M14: 0.26665013 | V14: 608.8363 | W14: =V14/V13-1 -> -0.0085091787 | Z14: 300.92834 | AA14: =Z14/Z13-1 -> 0.023829254 | AC14: 3470.9106 | AD14: =AC14/AC13-1 -> 0.020447641 | AF14: 1466.9786 | AG14: =AF14/AF13-1 -> -0.0066158166
B15: 45565 | C15: 3008.366 | D15: =C15/C14-1 -> -0.071962541 | F15: 25014.6 | G15: =F15/F14-1 -> -0.04447656 | L15: Standard Error | M15: 0.029303635 | V15: 568.80914 | W15: =V15/V14-1 -> -0.065743715 | Z15: 284.14798 | AA15: =Z15/Z14-1 -> -0.055761995 | AC15: 3505.6392 | AD15: =AC15/AC14-1 -> 0.010005592 | AF15: 1455.9625 | AG15: =AF15/AF14-1 -> -0.007509389
B16: 45572 | C16: 2973.803 | D16: =C16/C15-1 -> -0.011488957 | F16: 24964.25 | G16: =F16/F15-1 -> -0.0020128089 | L16: Observations | M16: 104 | V16: 563.48529 | W16: =V16/V15-1 -> -0.0093596466 | Z16: 280.88913 | AA16: =Z16/Z15-1 -> -0.011468848 | AC16: 3782.9192 | AD16: =AC16/AC15-1 -> 0.079095428 | AF16: 1477.3467 | AG16: =AF16/AF15-1 -> 0.014687298
B17: 45579 | C17: 2929.6929 | D17: =C17/C16-1 -> -0.014832895 | F17: 24854.051 | G17: =F17/F16-1 -> -0.0044142812 | V17: 548.49982 | W17: =V17/V16-1 -> -0.026594259 | Z17: 279.23544 | AA17: =Z17/Z16-1 -> -0.0058873283 | AC17: 3588.3555 | AD17: =AC17/AC16-1 -> -0.051432164 | AF17: 1562.0856 | AG17: =AF17/AF16-1 -> 0.05735884
